
<robot name="pointRobot">
  <material name="blue">
      <color rgba="0 0 0.8 1"/>
  </material>
  <material name="red">
      <color rgba="0.8 0 0.0 1"/>
  </material>
  <material name="green">
        <color rgba="0 0.8 0.0 1"/>
  </material>
  <link name="world"/>
  <link name="big_planck">

    <visual>
      <geometry>
        <box size="0.8 0.8 0.05"/>
      </geometry>
      <material name="green"/>
    </visual>
    <collision>
      <geometry>
        <box size="0.8 0.8 0.05"/>
      </geometry>
    </collision>
    <inertial>
      <mass value="1"/>
      <inertia ixx="1" ixy="0" ixz="0" iyy="1" iyz="0" izz="1"/>
      </inertial>
    </link>


  <link name="holder_right">
      <inertial>
      <mass value="0.1"/>
      <origin rpy="0 0 0" xyz="0 0 0"/>
      <inertia ixx="0.01" ixy="0.0" ixz="0.0" iyy="0.01" iyz="0.0" izz="0.01"/>
      </inertial>
    <visual>
      <geometry>
        <box size="0.1 0.1 0.1"/>
      </geometry>
      <material name="blue"/>
    </visual>
    </link>

  <link name="holder_left">
      <inertial>
      <mass value="0.1"/>
      <origin rpy="0 0 0" xyz="0 0 0"/>
      <inertia ixx="0.01" ixy="0.0" ixz="0.0" iyy="0.01" iyz="0.0" izz="0.01"/>
      </inertial>
    <visual>
      <geometry>
        <box size="0.1 0.1 0.1"/>
      </geometry>
      <material name="blue"/>
    </visual>
    </link>
   <link name="holder_top">
      <inertial>
      <mass value="0.1"/>
      <origin rpy="0 0 0" xyz="0 0 0"/>
      <inertia ixx="0.01" ixy="0.0" ixz="0.0" iyy="0.01" iyz="0.0" izz="0.01"/>
      </inertial>
    <visual>
      <geometry>
        <box size="0.1 0.2 0.1"/>
      </geometry>
      <material name="blue"/>
    </visual>
    </link>

  <link name="base_link_x_1">
    <inertial>
      <mass value="1.0"/>
      <origin rpy="0 0 0" xyz="0 0 0"/>
      <inertia ixx="1.0" ixy="0.0" ixz="0.0" iyy="1.0" iyz="0.0" izz="1.0"/>
    </inertial>
  </link>
  <link name="base_link_y_1">
    <inertial>
      <mass value="1.0"/>
      <origin rpy="0 0 0" xyz="0 0 0"/>
      <inertia ixx="1.0" ixy="0.0" ixz="0.0" iyy="1.0" iyz="0.0" izz="1.0"/>
    </inertial>
  </link>

  <link name="base_link_1">
    <inertial>
      <mass value="100.0"/>
      <origin rpy="0 0 0" xyz="0 0 0"/>
      <inertia ixx="1.0" ixy="0.0" ixz="0.0" iyy="1.0" iyz="0.0" izz="1.0"/>
    </inertial>
    <collision>
      <origin rpy="0.0 0 0" xyz="0 0 0"/>
      <geometry>
          <cylinder length="0.1" radius="0.2"/>
      </geometry>
    </collision>
    <visual>
      <origin rpy="0.0 0 0" xyz="0 0 0"/>
      <geometry>
          <cylinder length="0.1" radius="0.2"/>
      </geometry>
    </visual>
  </link>
   <joint name="base_to_holder" type="fixed">
     <parent link="base_link_1"/>
      <child link="holder_right"/>
      <origin xyz="0 -0.10 0.10"/>
</joint>
<joint name="base_to_holder_left" type="fixed">
      <parent link="base_link_1"/>
        <child link="holder_left"/>
        <origin xyz="0 0.10 0.10"/>
</joint>
<joint name="base_to_holder_top" type="fixed">
      <parent link="base_link_1"/>
        <child link="holder_top"/>
        <origin xyz="0 0 0.20"/>
</joint>
<joint name="base_to_big_planck" type="fixed">
      <parent link="base_link_1"/>
        <child link="big_planck"/>
        <origin xyz="0 0 0.20"/>
</joint>
  <link name="lidar_link_1">
    <inertial>
      <mass value="100.0"/>
      <origin rpy="0 0 0" xyz="0 0 0"/>
      <inertia ixx="1.0" ixy="0.0" ixz="0.0" iyy="1.0" iyz="0.0" izz="1.0"/>
    </inertial>
    <collision>
      <origin rpy="0.0 0 0" xyz="0 0 0"/>
      <geometry>
          <cylinder length="0.1" radius="0.02"/>
      </geometry>
    </collision>
    <visual>
      <origin rpy="0.0 0 0" xyz="0 0 0"/>
      <geometry>
          <cylinder length="0.1" radius="0.02"/>
      </geometry>
      <material name="blue"/>
    </visual>
  </link>
  <link name="feature_link_1">
    <inertial>
      <mass value="1.0"/>
      <origin rpy="0 0 0" xyz="0 0 0"/>
      <inertia ixx="1.0" ixy="0.0" ixz="0.0" iyy="1.0" iyz="0.0" izz="1.0"/>
    </inertial>
    <collision>
      <origin rpy="0.0 0 0" xyz="0 0 0"/>
      <geometry>
          <cylinder length="0.001" radius="0.02"/>
      </geometry>
    </collision>
    <visual>
      <origin rpy="0.0 0 0" xyz="0 0 0"/>
      <geometry>
          <cylinder length="0.001" radius="0.02"/>
      </geometry>
      <material name="red"/>
    </visual>
  </link>
  <link name="lidar_sensor_link_1"/>
      <inertial>
      <mass value="0.1"/>
      <origin rpy="0 0 0" xyz="0 0 0"/>
      <inertia ixx="0.01" ixy="0.0" ixz="0.0" iyy="0.01" iyz="0.0" izz="0.01"/>
    </inertial>
  <joint name="mobile_joint_x_1" type="prismatic">
    <safety_controller k_position="100.0" k_velocity="40.0" soft_lower_limit="-2.8973" soft_upper_limit="2.8973"/>
    <parent link="world"/>
    <child link="base_link_x_1"/>
    <origin rpy="0 0 0" xyz="0 0 0.05"/>
    <axis xyz="1 0 0"/>
    <limit effort="87" lower="-5" upper="5" velocity="2.1750"/>
  </joint>
  <joint name="mobile_joint_y_1" type="prismatic">
    <safety_controller k_position="100.0" k_velocity="40.0" soft_lower_limit="-2.8973" soft_upper_limit="2.8973"/>
    <parent link="base_link_x_1"/>
    <child link="base_link_y_1"/>
    <origin rpy="0 0 0" xyz="0 0 0"/>
    <axis xyz="0 1 0"/>
    <limit effort="87" lower="-5" upper="5" velocity="2.1750"/>
  </joint>
  <joint name="mobile_joint_theta_1" type="revolute">
    <parent link="base_link_y_1"/>
    <child link="base_link_1"/>
    <origin rpy="0 0 0" xyz="0 0 0"/>
    <axis xyz="0 0 1"/>
    <limit effort="87" lower="-5" upper="5" velocity="2.1750"/>
  </joint>
  <joint name="robot_lidar_1" type="fixed">
    <parent link="base_link_1"/>
    <child link="lidar_link_1"/>
    <origin rpy="0 0 0" xyz="0 0 0.1"/>
  </joint>
  <joint name="lidar_sensor_joint_1" type="fixed">
    <parent link="lidar_link_1"/>
    <child link="lidar_sensor_link_1"/>
    <origin rpy="0 0 0" xyz="0 0 0.1"/>
  </joint>
  <joint name="feature_link_joint_1" type='fixed'>
    <parent link="base_link_1"/>
    <child link="feature_link_1"/>
    <origin rpy="0 0 0" xyz="0 0.1 0.0505"/>
  </joint>
</robot>